[2025-06-16 03:28:09 +0000] [4400] [INFO] Starting gunicorn 23.0.0
[2025-06-16 03:28:09 +0000] [4400] [INFO] Listening at: http://0.0.0.0:5000 (4400)
[2025-06-16 03:28:09 +0000] [4400] [INFO] Using worker: sync
[2025-06-16 03:28:09 +0000] [4411] [INFO] Booting worker with pid: 4411
[2025-06-16 03:28:09 +0000] [4400] [INFO] Handling signal: winch
[2025-06-16 03:28:10 +0000] [4400] [INFO] Handling signal: winch
[2025-06-16 03:28:10 +0000] [4400] [INFO] Handling signal: winch
[2025-06-16 03:28:10 +0000] [4400] [INFO] Handling signal: winch
[2025-06-16 03:28:10 +0000] [4400] [INFO] Handling signal: winch
[2025-06-16 03:28:10 +0000] [4400] [INFO] Handling signal: winch
[2025-06-16 03:28:10 +0000] [4400] [INFO] Handling signal: winch
[2025-06-16 03:28:10 +0000] [4411] [ERROR] Exception in worker process
Traceback (most recent call last):
  File "/home/runner/workspace/.pythonlibs/lib/python3.11/site-packages/gunicorn/arbiter.py", line 608, in spawn_worker
    worker.init_process()
  File "/home/runner/workspace/.pythonlibs/lib/python3.11/site-packages/gunicorn/workers/base.py", line 135, in init_process
    self.load_wsgi()
  File "/home/runner/workspace/.pythonlibs/lib/python3.11/site-packages/gunicorn/workers/base.py", line 147, in load_wsgi
    self.wsgi = self.app.wsgi()
                ^^^^^^^^^^^^^^^
  File "/home/runner/workspace/.pythonlibs/lib/python3.11/site-packages/gunicorn/app/base.py", line 66, in wsgi
    self.callable = self.load()
                    ^^^^^^^^^^^
  File "/home/runner/workspace/.pythonlibs/lib/python3.11/site-packages/gunicorn/app/wsgiapp.py", line 57, in load
    return self.load_wsgiapp()
           ^^^^^^^^^^^^^^^^^^^
  File "/home/runner/workspace/.pythonlibs/lib/python3.11/site-packages/gunicorn/app/wsgiapp.py", line 47, in load_wsgiapp
    return util.import_app(self.app_uri)
           ^^^^^^^^^^^^^^^^^^^^^^^^^^^^^
  File "/home/runner/workspace/.pythonlibs/lib/python3.11/site-packages/gunicorn/util.py", line 370, in import_app
    mod = importlib.import_module(module)
          ^^^^^^^^^^^^^^^^^^^^^^^^^^^^^^^
  File "/nix/store/clx0mcir7qw8zk36zbr4jra789g3knf6-python3-3.11.10/lib/python3.11/importlib/__init__.py", line 126, in import_module
    return _bootstrap._gcd_import(name[level:], package, level)
           ^^^^^^^^^^^^^^^^^^^^^^^^^^^^^^^^^^^^^^^^^^^^^^^^^^^^
  File "<frozen importlib._bootstrap>", line 1204, in _gcd_import
  File "<frozen importlib._bootstrap>", line 1176, in _find_and_load
  File "<frozen importlib._bootstrap>", line 1147, in _find_and_load_unlocked
  File "<frozen importlib._bootstrap>", line 690, in _load_unlocked
  File "<frozen importlib._bootstrap_external>", line 940, in exec_module
  File "<frozen importlib._bootstrap>", line 241, in _call_with_frames_removed
  File "/home/runner/workspace/main.py", line 1, in <module>
    from app import app  # noqa: F401
    ^^^^^^^^^^^^^^^^^^^
  File "/home/runner/workspace/app.py", line 10, in <module>
    from notification_system import notification_system, NotificationType, NotificationPriority
  File "/home/runner/workspace/notification_system.py", line 10, in <module>
    from email.mime.text import MimeText
ImportError: cannot import name 'MimeText' from 'email.mime.text' (/nix/store/clx0mcir7qw8zk36zbr4jra789g3knf6-python3-3.11.10/lib/python3.11/email/mime/text.py)
[2025-06-16 03:28:10 +0000] [4411] [INFO] Worker exiting (pid: 4411)
[2025-06-16 03:28:10 +0000] [4400] [INFO] Handling signal: winch
[2025-06-16 03:28:10 +0000] [4400] [ERROR] Worker (pid:4411) exited with code 3
[2025-06-16 03:28:10 +0000] [4400] [ERROR] Shutting down: Master
[2025-06-16 03:28:10 +0000] [4400] [ERROR] Reason: Worker failed to boot.